<?xml version="1.0" ?>
<!-- =================================================================================== -->
<!-- |    This document was autogenerated by xacro from ruka.urdf.xacro                | -->
<!-- |    EDITING THIS FILE BY HAND IS NOT RECOMMENDED                                 | -->
<!-- =================================================================================== -->
<robot name="my_robot_arm" xmlns:xacro="http://ros.org/wiki/xacro">
  <link name="base_link">
    <visual>
      <origin rpy="0 0 0" xyz="0 0 0"/>
      <geometry>
        <box size="0.5 0.5 0.1"/>
      </geometry>
      <material name="grey">
        <color rgba="0.5 0.5 0.5 1.0"/>
      </material>
    </visual>
  </link>
  <!-- part1 -->
  <link name="part1">
    <visual>
      <origin rpy="0 0 0" xyz="0 0 0"/>
      <geometry>
        <mesh filename="niki_arm.stl" scale="0.01 0.01 0.01"/>
      </geometry>
    </visual>
  </link>
  <joint name="joint1" type="revolute">
    <parent link="base_link"/>
    <child link="part1"/>
    <origin rpy="0 0 0" xyz="0 0 0.05"/>
    <axis xyz="0 0 1"/>
    <limit effort="10" lower="-3.141592653589793" upper="3.141592653589793" velocity="1.0"/>
  </joint>
  <!-- part2 -->
  <link name="part2">
    <visual>
      <origin rpy="0 0 0" xyz="0 0 0"/>
      <geometry>
        <mesh filename="niki_arm.stl" scale="0.01 0.01 0.01"/>
      </geometry>
    </visual>
  </link>
  <joint name="joint2" type="revolute">
    <parent link="part1"/>
    <child link="part2"/>
    <origin rpy="1.0471975511965976 0 0" xyz="               0                -0.40000000000000013                0.7110254037844386"/>
    <axis xyz="0 0 1"/>
    <limit effort="10" lower="-3.141592653589793" upper="3.141592653589793" velocity="1.0"/>
  </joint>
  <!-- part3-->
  <link name="part3">
    <visual>
      <origin rpy="0 0 0" xyz="0 0 0"/>
      <geometry>
        <mesh filename="niki_arm.stl" scale="0.01 0.01 0.01"/>
      </geometry>
    </visual>
  </link>
  <joint name="joint3" type="revolute">
    <parent link="part2"/>
    <child link="part3"/>
    <origin rpy="1.0471975511965976 0 0" xyz="               0                -0.40000000000000013                0.7110254037844386"/>
    <axis xyz="0 0 1"/>
    <limit effort="10" lower="-3.141592653589793" upper="3.141592653589793" velocity="1.0"/>
  </joint>
  <!-- part4 -->
  <link name="part4">
    <visual>
      <origin rpy="0 0 0" xyz="0 0 0"/>
      <geometry>
        <mesh filename="niki_arm.stl" scale="0.01 0.01 0.01"/>
      </geometry>
    </visual>
  </link>
  <joint name="joint4" type="revolute">
    <parent link="part3"/>
    <child link="part4"/>
    <origin rpy="1.0471975511965976 0 0" xyz="               0                -0.40000000000000013                0.7110254037844386"/>
    <axis xyz="0 0 1"/>
    <limit effort="10" lower="-3.141592653589793" upper="3.141592653589793" velocity="1.0"/>
  </joint>
  <!---->
  <!-- part5 -->
  <!---->
  <!--<link name="part5">-->
  <!--	<visual>-->
  <!--		<origin xyz="0 0 0" rpy="0 0 0" />-->
  <!--		<geometry>-->
  <!--			<mesh filename="niki_arm.stl" scale="0.01 0.01 0.01" />-->
  <!--		</geometry>-->
  <!--	</visual>-->
  <!--</link>-->
  <!---->
  <!--<joint name="joint5" type="revolute">-->
  <!--	<parent link="part4" />-->
  <!--	<child link="part5" />-->
  <!--	<origin xyz="${subsequent_joint_xyz}" rpy="${subsequent_joint_rpy}" />-->
  <!--	<axis xyz="0 0 1" />-->
  <!--	<limit lower="-${pi}" upper="${pi}" effort="10" velocity="1.0" />-->
  <!--</joint>-->
  <!---->
  <!-- part6 -->
  <!---->
  <!--<link name="part6">-->
  <!--	<visual>-->
  <!--		<origin xyz="0 0 0" rpy="0 0 0" />-->
  <!--		<geometry>-->
  <!--			<mesh filename="niki_arm.stl" scale="0.01 0.01 0.01" />-->
  <!--		</geometry>-->
  <!--	</visual>-->
  <!--</link>-->
  <!---->
  <!--<joint name="joint6" type="revolute">-->
  <!--	<parent link="part5" />-->
  <!--	<child link="part6" />-->
  <!--	<origin xyz="${subsequent_joint_xyz}" rpy="${subsequent_joint_rpy}" />-->
  <!--	<axis xyz="0 0 1" />-->
  <!--	<limit lower="-${pi}" upper="${pi}" effort="10" velocity="1.0" />-->
  <!--</joint>-->
  <!---->
</robot>

