<?xml version="1.0" ?>
<!-- =================================================================================== -->
<!-- |    This document was autogenerated by xacro from transitiom_with_inertia.xacro  | -->
<!-- |    EDITING THIS FILE BY HAND IS NOT RECOMMENDED                                 | -->
<!-- =================================================================================== -->
<robot name="my_robot_arm" xmlns:xacro="http://ros.org/wiki/xacro">
  <!-- Base link -->
  <link name="base_link">
    <visual>
      <origin rpy="0 0 0" xyz="0 0 0"/>
      <geometry>
        <box size="0.5 0.5 0.1"/>
      </geometry>
      <material name="grey">
        <color rgba="0.5 0.5 0.5 1.0"/>
      </material>
    </visual>
    <!-- Added inertial for base_link -->
    <inertial>
      <origin rpy="0 0 0" xyz="0 0 0"/>
      <mass value="1.0"/>
      <inertia ixx="0.01" ixy="0.0" ixz="0.0" iyy="0.01" iyz="0.0" izz="0.01"/>
    </inertial>
  </link>
  <!-- part1 -->
  <link name="part1">
    <visual>
      <origin rpy="0 0 0" xyz="0 0 0"/>
      <geometry>
        <mesh filename="niki_arm.stl" scale="0.01 0.01 0.01"/>
      </geometry>
    </visual>
    <collision>
      <origin rpy="0 0 0" xyz="0 0 0"/>
      <geometry>
        <mesh filename="niki_arm.stl" scale="0.01 0.01 0.01"/>
      </geometry>
    </collision>
    <!-- Added inertial for part1 -->
    <inertial>
      <origin rpy="0 0 0" xyz="0 0 0"/>
      <mass value="1.0"/>
      <inertia ixx="0.01" ixy="0.0" ixz="0.0" iyy="0.01" iyz="0.0" izz="0.01"/>
    </inertial>
  </link>
  <joint name="joint1" type="revolute">
    <parent link="base_link"/>
    <child link="part1"/>
    <origin rpy="0 0 0" xyz="0 0 0.05"/>
    <axis xyz="0 0 1"/>
    <!-- Increased effort for stronger drive -->
    <limit effort="100" lower="-3.141592653589793" upper="3.141592653589793" velocity="1.0"/>
    <dynamics damping="2.0" friction="0.2"/>
  </joint>
  <!-- part2 -->
  <link name="part2">
    <visual>
      <origin rpy="0 0 0" xyz="0 0 0"/>
      <geometry>
        <mesh filename="niki_arm.stl" scale="0.01 0.01 0.01"/>
      </geometry>
    </visual>
    <collision>
      <origin rpy="0 0 0" xyz="0 0 0"/>
      <geometry>
        <mesh filename="niki_arm.stl" scale="0.01 0.01 0.01"/>
      </geometry>
    </collision>
    <!-- Added inertial for part2 -->
    <inertial>
      <origin rpy="0 0 0" xyz="0 0 0"/>
      <mass value="1.0"/>
      <inertia ixx="0.01" ixy="0.0" ixz="0.0" iyy="0.01" iyz="0.0" izz="0.01"/>
    </inertial>
  </link>
  <joint name="joint2" type="revolute">
    <parent link="part1"/>
    <child link="part2"/>
    <origin rpy="1.0471975511965976 0 0" xyz="0 -0.40000000000000013 0.7110254037844386"/>
    <axis xyz="0 0 1"/>
    <limit effort="100" lower="-3.141592653589793" upper="3.141592653589793" velocity="1.0"/>
    <dynamics damping="2.0" friction="0.2"/>
  </joint>
  <!-- part3 -->
  <link name="part3">
    <visual>
      <origin rpy="0 0 0" xyz="0 0 0"/>
      <geometry>
        <mesh filename="niki_arm.stl" scale="0.01 0.01 0.01"/>
      </geometry>
    </visual>
    <collision>
      <origin rpy="0 0 0" xyz="0 0 0"/>
      <geometry>
        <mesh filename="niki_arm.stl" scale="0.01 0.01 0.01"/>
      </geometry>
    </collision>
    <!-- Added inertial for part3 -->
    <inertial>
      <origin rpy="0 0 0" xyz="0 0 0"/>
      <mass value="1.0"/>
      <inertia ixx="0.01" ixy="0.0" ixz="0.0" iyy="0.01" iyz="0.0" izz="0.01"/>
    </inertial>
  </link>
  <joint name="joint3" type="revolute">
    <parent link="part2"/>
    <child link="part3"/>
    <origin rpy="1.0471975511965976 0 0" xyz="0 -0.40000000000000013 0.7110254037844386"/>
    <axis xyz="0 0 1"/>
    <limit effort="100" lower="-3.141592653589793" upper="3.141592653589793" velocity="1.0"/>
    <dynamics damping="2.0" friction="0.2"/>
  </joint>
  <!-- part4 -->
  <link name="part4">
    <visual>
      <origin rpy="0 0 0" xyz="0 0 0"/>
      <geometry>
        <mesh filename="niki_arm.stl" scale="0.01 0.01 0.01"/>
      </geometry>
    </visual>
    <collision>
      <origin rpy="0 0 0" xyz="0 0 0"/>
      <geometry>
        <mesh filename="niki_arm.stl" scale="0.01 0.01 0.01"/>
      </geometry>
    </collision>
    <!-- Added inertial for part4 -->
    <inertial>
      <origin rpy="0 0 0" xyz="0 0 0"/>
      <mass value="1.0"/>
      <inertia ixx="0.01" ixy="0.0" ixz="0.0" iyy="0.01" iyz="0.0" izz="0.01"/>
    </inertial>
  </link>
  <joint name="joint4" type="revolute">
    <parent link="part3"/>
    <child link="part4"/>
    <origin rpy="1.0471975511965976 0 0" xyz="0 -0.40000000000000013 0.7110254037844386"/>
    <axis xyz="0 0 1"/>
    <limit effort="100" lower="-3.141592653589793" upper="3.141592653589793" velocity="1.0"/>
    <dynamics damping="2.0" friction="0.2"/>
  </joint>
  <!-- part5 -->
  <link name="part5">
    <visual>
      <origin rpy="0 0 0" xyz="0 0 0"/>
      <geometry>
        <mesh filename="niki_arm.stl" scale="0.01 0.01 0.01"/>
      </geometry>
    </visual>
    <collision>
      <origin rpy="0 0 0" xyz="0 0 0"/>
      <geometry>
        <mesh filename="niki_arm.stl" scale="0.01 0.01 0.01"/>
      </geometry>
    </collision>
    <!-- Added inertial for part5 -->
    <inertial>
      <origin rpy="0 0 0" xyz="0 0 0"/>
      <mass value="1.0"/>
      <inertia ixx="0.01" ixy="0.0" ixz="0.0" iyy="0.01" iyz="0.0" izz="0.01"/>
    </inertial>
  </link>
  <joint name="joint5" type="revolute">
    <parent link="part4"/>
    <child link="part5"/>
    <origin rpy="1.0471975511965976 0 0" xyz="0 -0.40000000000000013 0.7110254037844386"/>
    <axis xyz="0 0 1"/>
    <limit effort="100" lower="-3.141592653589793" upper="3.141592653589793" velocity="1.0"/>
    <dynamics damping="2.0" friction="0.2"/>
  </joint>
  <!-- part6 -->
  <link name="part6">
    <visual>
      <origin rpy="0 0 0" xyz="0 0 0"/>
      <geometry>
        <mesh filename="niki_arm.stl" scale="0.01 0.01 0.01"/>
      </geometry>
    </visual>
    <collision>
      <origin rpy="0 0 0" xyz="0 0 0"/>
      <geometry>
        <mesh filename="niki_arm.stl" scale="0.01 0.01 0.01"/>
      </geometry>
    </collision>
    <!-- Added inertial for part6 -->
    <inertial>
      <origin rpy="0 0 0" xyz="0 0 0"/>
      <mass value="1.0"/>
      <inertia ixx="0.01" ixy="0.0" ixz="0.0" iyy="0.01" iyz="0.0" izz="0.01"/>
    </inertial>
  </link>
  <joint name="joint6" type="revolute">
    <parent link="part5"/>
    <child link="part6"/>
    <origin rpy="1.0471975511965976 0 0" xyz="0 -0.40000000000000013 0.7110254037844386"/>
    <axis xyz="0 0 1"/>
    <limit effort="100" lower="-3.141592653589793" upper="3.141592653589793" velocity="1.0"/>
    <dynamics damping="2.0" friction="0.2"/>
  </joint>
  <!-- Gripper base -->
  <link name="gripper_base">
    <visual>
      <origin rpy="0 0 0" xyz="0 -0.1 0"/>
      <geometry>
        <box size="0.8 0.1 0.4"/>
      </geometry>
      <material name="white">
        <color rgba="1 1 1 1"/>
      </material>
    </visual>
    <collision>
      <origin rpy="0 0 0" xyz="0 -0.1 0"/>
      <geometry>
        <box size="0.8 0.1 0.4"/>
      </geometry>
    </collision>
    <!-- Added inertial for gripper_base -->
    <inertial>
      <origin rpy="0 0 0" xyz="0 0 0"/>
      <mass value="0.5"/>
      <inertia ixx="0.005" ixy="0.0" ixz="0.0" iyy="0.005" iyz="0.0" izz="0.005"/>
    </inertial>
  </link>
  <joint name="gripper_to_part6" type="fixed">
    <parent link="part6"/>
    <child link="gripper_base"/>
    <origin rpy="-0.5235987755982988 0 0" xyz="0 -0.40000000000000013 0.7110254037844386"/>
  </joint>
  <!-- Left fingertip -->
  <link name="left_fingertip">
    <visual>
      <origin rpy="0 0 0" xyz="0 0 0"/>
      <geometry>
        <box size="0.1 0.4 0.1"/>
      </geometry>
      <material name="white">
        <color rgba="1 1 1 1"/>
      </material>
    </visual>
    <collision>
      <origin rpy="0 0 0" xyz="0 0 0"/>
      <geometry>
        <box size="0.1 0.4 0.1"/>
      </geometry>
    </collision>
    <!-- Added inertial for left_fingertip -->
    <inertial>
      <origin rpy="0 0 0" xyz="0 0 0"/>
      <mass value="0.2"/>
      <inertia ixx="0.002" ixy="0.0" ixz="0.0" iyy="0.002" iyz="0.0" izz="0.002"/>
    </inertial>
  </link>
  <joint name="base_to_left_fingertip" type="prismatic">
    <origin xyz="-0.35 -0.4 0.0"/>
    <parent link="gripper_base"/>
    <child link="left_fingertip"/>
    <axis xyz="1 0 0"/>
    <limit effort="5.0" lower="0" upper="0.3" velocity="0.5"/>
    <dynamics damping="1.0" friction="0.1"/>
  </joint>
  <!-- Right fingertip -->
  <link name="right_fingertip">
    <visual>
      <origin rpy="0 0 0" xyz="0 0 0"/>
      <geometry>
        <box size="0.1 0.4 0.1"/>
      </geometry>
      <material name="white">
        <color rgba="1 1 1 1"/>
      </material>
    </visual>
    <collision>
      <origin rpy="0 0 0" xyz="0 0 0"/>
      <geometry>
        <box size="0.1 0.4 0.1"/>
      </geometry>
    </collision>
    <!-- Added inertial for right_fingertip -->
    <inertial>
      <origin rpy="0 0 0" xyz="0 0 0"/>
      <mass value="0.2"/>
      <inertia ixx="0.002" ixy="0.0" ixz="0.0" iyy="0.002" iyz="0.0" izz="0.002"/>
    </inertial>
  </link>
  <joint name="base_to_right_fingertip" type="prismatic">
    <origin xyz="0.35 -0.4 0.0"/>
    <parent link="gripper_base"/>
    <child link="right_fingertip"/>
    <axis xyz="1 0 0"/>
    <limit effort="5.0" lower="-0.3" upper="0.0" velocity="0.5"/>
    <dynamics damping="1.0" friction="0.1"/>
  </joint>
  <!-- Transmissions: Adding gear reduction (32:1) to mimic stepper motor behavior -->
  <transmission name="trans_joint1">
    <type>transmission_interface/SimpleTransmission</type>
    <joint name="joint1">
      <hardwareInterface>EffortJointInterface</hardwareInterface>
    </joint>
    <actuator name="motor_joint1">
      <hardwareInterface>EffortJointInterface</hardwareInterface>
      <mechanicalReduction>32</mechanicalReduction>
    </actuator>
  </transmission>
  <transmission name="trans_joint2">
    <type>transmission_interface/SimpleTransmission</type>
    <joint name="joint2">
      <hardwareInterface>EffortJointInterface</hardwareInterface>
    </joint>
    <actuator name="motor_joint2">
      <hardwareInterface>EffortJointInterface</hardwareInterface>
      <mechanicalReduction>32</mechanicalReduction>
    </actuator>
  </transmission>
  <transmission name="trans_joint3">
    <type>transmission_interface/SimpleTransmission</type>
    <joint name="joint3">
      <hardwareInterface>EffortJointInterface</hardwareInterface>
    </joint>
    <actuator name="motor_joint3">
      <hardwareInterface>EffortJointInterface</hardwareInterface>
      <mechanicalReduction>32</mechanicalReduction>
    </actuator>
  </transmission>
  <transmission name="trans_joint4">
    <type>transmission_interface/SimpleTransmission</type>
    <joint name="joint4">
      <hardwareInterface>EffortJointInterface</hardwareInterface>
    </joint>
    <actuator name="motor_joint4">
      <hardwareInterface>EffortJointInterface</hardwareInterface>
      <mechanicalReduction>32</mechanicalReduction>
    </actuator>
  </transmission>
  <transmission name="trans_joint5">
    <type>transmission_interface/SimpleTransmission</type>
    <joint name="joint5">
      <hardwareInterface>EffortJointInterface</hardwareInterface>
    </joint>
    <actuator name="motor_joint5">
      <hardwareInterface>EffortJointInterface</hardwareInterface>
      <mechanicalReduction>32</mechanicalReduction>
    </actuator>
  </transmission>
  <transmission name="trans_joint6">
    <type>transmission_interface/SimpleTransmission</type>
    <joint name="joint6">
      <hardwareInterface>EffortJointInterface</hardwareInterface>
    </joint>
    <actuator name="motor_joint6">
      <hardwareInterface>EffortJointInterface</hardwareInterface>
      <mechanicalReduction>32</mechanicalReduction>
    </actuator>
  </transmission>
</robot>